Workbook
Name access_method: glossary!#REF!
Name access_method: nametitle_modappl!#REF!
Name age_class_adult: glossary!$E$18
Name age_class_adult: nametitle_modappl!#REF!
Name age_class_juvenile: glossary!$E$41
Name age_class_juvenile: nametitle_modappl!#REF!
Name age_class_subadult_yearling: glossary!$E$64
Name age_class_subadult_yearling: nametitle_modappl!#REF!
Name age_class_subadult_youngofyear: glossary!$E$65
Name age_class_subadult_youngofyear: nametitle_modappl!#REF!
Name analyst: glossary!$E$20
Name analyst: nametitle_modappl!#REF!
Name animal_id: glossary!#REF!
Name animal_id: nametitle_modappl!#REF!
Name baitlure_audible_lure: glossary!$E$75
Name baitlure_audible_lure: nametitle_modappl!#REF!
Name baitlure_bait_lure_type: glossary!$E$21
Name baitlure_bait_lure_type: nametitle_modappl!#REF!
Name baitlure_lure: glossary!#REF!
Name baitlure_lure: nametitle_modappl!#REF!
Name baitlure_scent_lure: glossary!$E$117
Name baitlure_scent_lure: nametitle_modappl!#REF!
Name baitlure_visual_lure: glossary!$E$148
Name baitlure_visual_lure: nametitle_modappl!#REF!
Name batteries_replaced: glossary!#REF!
Name batteries_replaced: nametitle_modappl!#REF!
Name behaviour: glossary!#REF!
Name behaviour: nametitle_modappl!#REF!
Name camera_active_on_arrival: glossary!#REF!
Name camera_active_on_arrival: nametitle_modappl!#REF!
Name camera_active_on_departure: glossary!#REF!
Name camera_active_on_departure: nametitle_modappl!#REF!
Name camera_angle: glossary!$E$78
Name camera_angle: nametitle_modappl!#REF!
Name camera_attachment: glossary!#REF!
Name camera_attachment: nametitle_modappl!#REF!
Name camera_damaged: glossary!#REF!
Name camera_damaged: nametitle_modappl!#REF!
Name camera_days_per_camera_location: glossary!$E$79
Name camera_days_per_camera_location: nametitle_modappl!#REF!
Name camera_direction: glossary!#REF!
Name camera_direction: nametitle_modappl!#REF!
Name camera_height: glossary!$E$22
Name camera_height: nametitle_modappl!#REF!
Name camera_id: glossary!$E$23
Name camera_id: nametitle_modappl!#REF!
Name camera_location_characteristics: glossary!#REF!
Name camera_location_characteristics: nametitle_modappl!#REF!
Name camera_location_comments: glossary!#REF!
Name camera_location_comments: nametitle_modappl!#REF!
Name camera_location_name: glossary!$E$24
Name camera_location_name: nametitle_modappl!#REF!
Name camera_make: glossary!$E$25
Name camera_make: nametitle_modappl!#REF!
Name camera_model: glossary!$E$26
Name camera_model: nametitle_modappl!#REF!
Name camera_serial_number: glossary!$E$27
Name camera_serial_number: nametitle_modappl!#REF!
Name camera_spacing: glossary!$E$81
Name camera_spacing: nametitle_modappl!#REF!

Sheet FIX
A2: TOC | B2: 01_31_sp_size_multi
A3: TOC | B3: 01_51_num_det_individ
A5: tooltips | B5: [modelling approaches](#mod_approach)

Sheet ADD
A1: from | B1: from2 | C1: key | D1: field_text_upper | E1: definition | F1: tip_id_upper | G1: field_text_lower | H1: tip_id_lower | I1: tooltip | K1: lookup_exact
C2: covariate | D2: Covariate | F2: =C2&"_tu" -> covariate_tu | G2: =LOWER(D2) -> covariate | H2: =C2&"_tl" -> covariate_tl
C3: distribution | D3: Distribution | F3: =C3&"_tu" -> distribution_tu | G3: =LOWER(D3) -> distribution | H3: =C3&"_tl" -> distribution_tl
C4: independence | D4: Independence | F4: =C4&"_tu" -> independence_tu | G4: =LOWER(D4) -> independence | H4: =C4&"_tl" -> independence_tl
C5: home_range | D5: Home ranges | F5: =C5&"_tu" -> home_range_tu | G5: =LOWER(D5) -> home ranges | H5: =C5&"_tl" -> home_range_tl
C6: sp_accum_asymptote | D6: Species-accumulation asymptote | F6: =C6&"_tu" -> sp_accum_asymptote_tu | G6: =LOWER(D6) -> species-accumulation asymptote | H6: =C6&"_tl" -> sp_accum_asymptote_tl
C7: data_distr_para | D7: Parametric distribution | F7: =C7&"_tu" -> data_distr_para_tu | G7: =LOWER(D7) -> parametric distribution | H7: =C7&"_tl" -> data_distr_para_tl
C8: data_distr_poisson | D8: Poisson-distributed | F8: =C8&"_tu" -> data_distr_poisson_tu | G8: =LOWER(D8) -> poisson-distributed | H8: =C8&"_tl" -> data_distr_poisson_tl
C9: closure_demo | D9: Demographic closure | F9: =C9&"_tu" -> closure_demo_tu | G9: =LOWER(D9) -> demographic closure | H9: =C9&"_tl" -> closure_demo_tl
C10: closure_geo | D10: Geographic closure | F10: =C10&"_tu" -> closure_geo_tu | G10: =LOWER(D10) -> geographic closure | H10: =C10&"_tl" -> closure_geo_tl
C11: closure_site | D11: Site closure | E11: the assumption that there is no change in state (e.g. species presence/ absence, immigration/ emigration, births/deaths) during the {{ survey_tl }} period ({{ rtxt_mackenzie_et_al_2004 }}).
C12: activity_centre | D12: Animals’ activity centres
C13: asymptotic | D13: Asymptotic
C14: captures | D14: Captures
C15: recaptures | D15: Recaptures
C16: data_auxiliary | D16: Auxiliary data
C17: adhoc | D17: Ad-hoc
C18: evenness | D18: Evenness
C19: categorical_id | D19: Categorical identifiers
C20: phenotypic | D20: Phenotypic
C21: rate_surivival | D21: Survival rate
C22: spatially_explicit | D22: Spatially explicit
C23: rate_recruitment | D23: Recruitment rate
... C31: colonization | D31: Site colonization
D32: Temporal interactions
D33: Effective area of detection
D34: cryptic
D35: elusive

Sheet ISSUES
A1: id | B1: intext | C1: intext2 | D1: textbib | E1: embed_url
A3: We have no analysis considerations to recommend based on your selections!<br>However, that doesn't mean that there aren't important aspects to consider. Please think through your design carefully to identify potential sources of bias and error.<br><br>Here is an example of what you might see in this section:<br><b>Because you chose...<em><br>State variable:</b> "Relative abundance" or "Unknown"</b></em><br><b>>>></b> Note that when you reach the analysis stage, you will want to select a count model method that most appropriately accounts for "Zero-inflation" and "Overdispersion" (see sections "Overdispersion/Zero-inflation [not yet present] and "Mixed models" [not yet present]).
A4: Based on your selections, none of the modeling approaches were appropriate, please review your selections to consider less restrictive options.<br>You can also refer to [Appendix A - Table A2](https://ab-rcsc.github.io/RCSC-WildCAM_Remote-Camera-Survey-Guidelines-and-Metadata-Standards/1_survey-guidelines/1_10.1_AppendixA-Tables.html) of the Remote Camera Survey Guidelines (RCSC et al., 2024) to determine what might be too restrictive (e.g., if you only have 10 cameras, you will see that few approaches are appropriate).
A8: Distance sampling | B8: In our third edition of the SEEC Stats Toolbox Seminars David Maphisa and Florian Weller explained how to conduct distance sampling. This method relies on either point counts or transect counts in which the distance from the observer to each animal or plant is recorded. These data are then used to estimate density or abundance while reducing observation bias. | D8: https://science.uct.ac.za/seec/stats-toolbox-seminars-spatial-and-species-distribution-toolboxes/distance-sampling
A9: Whitlock, Michael, and Dolph Schluter. The Analysis of Biological Data. Third. Book, Whole. New York;Austin;Plymouth;Boston; Macmillan Learning, 2020.
A10: Estimating survival from CMR data | B10: Altwegg, R. (2020). *SEEC Toolbox on estimating survival from CMR data.* <https://science.uct.ac.za/seec/stats-toolbox-seminars-spatial-and-species-distribution-toolboxes/estimating-survival-cmr-data>
A11: ??? | B11: https://science.uct.ac.za/seec/stats-toolbox-seminars/spatial-and-species-distribution-toolboxes
A14: ~*~*<font size=“4”><span style=“color:#2F5496”>How does this relate to study design?</font></span>~*~* | B14: h_how_relate_study_design | C14: {{ header_ | D14: }}
A15: ~*~*<font size=“4”><span style=“color:#2F5496”>How does that work?</font></span>~*~* | B15: h_how_does_it_work | C15: {{ sub_header_ | D15: }}
A16: ~*~*<font size=“4”><span style=“color:#2F5496”>Why do we care?</font></span>~*~* | B16: h_why_does_it_matter | C16: {{ sub_header_ | D16: }}
C17: {{ sub_header_ | D17: }}
C18: {{ sub_header_ | D18: }}
C19: {{ sub_header_ | D19: }}

Sheet glossary
A1: note | B1: key_order | C1: key_type | D1: mod | E1: field_name_text_format | F1: only_upper | G1: from | H1: from2 | I1: key_ref | J1: key | K1: field_text_upper | L1: in_find_replace | M1: definition | N1: tooltip | O1: substitution | P1: substitution2 | Q1: blank | R1: mandatory | S1: metadata | T1: [survey](/09_glossary.md#survey) | U1: xx | V1: tip_f2 | W1: tip_f3 | X1: tip_f4 | Y1: tip_formula | Z1: access_method_tu: "<a href=\"09_glossary.html#access_method\" target=\"_blank\" data-bs-toggle=\"tooltip\" data-bs-title=\"Access Method: The method used to reach the camera location (e.g., on 'Foot,' 'ATV,' 'Helicopter,' etc.).\">Access Method<button type=\"button\" class=\"btn btn-bd-tip-info-hidden btn-sm position-relative\">.<span class=\"position-absolute top-0 start-100 translate-middle\">{{ icon_info }}</span></button></a>"
B2: 107 | C2: field | D2: - | E2: **\*# Of Images** | F2: upper | G2: surv_guide_meta | H2: cam_visit_equip | I2: number_of_images | J2: =IF(D2<>"-",I2&"_"&D2,I2) -> number_of_images | K2: # Of Images | L2: =IF(VLOOKUP(J2,find_replace!H:H,1,"false")=J2,"TRUE","FALSE") -> TRUE | M2: The number of images on an SD card. | N2: The number of images on an SD card. | O2: =IF(M2=999,"",(" term_"&J2&": """&K2&"""")) -> term_number_of_images: "# Of Images" | P2: =IF(M2="-","-",(" def_"&J2&": """&M2&"""")) -> def_number_of_images: "The number of images on an SD card." | R2: FALSE | S2: TRUE | T2: TRUE | U2: xx | V2: \" target=\"_blank\" data-bs-toggle=\"tooltip\" data-bs-title=\" | W2: \"> | X2: <button type=\"button\" class=\"btn btn-bd-tip-info-hidden btn-sm position-relative\">.<span class=\"position-absolute top-0 start-100 translate-middle\">{{ icon_info }}</span></button></a> | Y2: =IF(M2<>"-",(" "&J2&"_ti"&": "&""""&"<a href=\"&""""&"09_glossary.html#"&J2&V2&K2&": "&M2&W2&""&X2&""""),"-") -> number_of_images_ti: "<a href=\"09_glossary.html#number_of_images\" target=\"_blank\" data-bs-toggle=\"tooltip\" data-bs-title=\"# Of Images: The number of images on an SD card.\"><button type=\"button\" class=\"btn btn-bd-tip-info-hidden btn-sm position-relative\">.<span class=\"position-absolute top-0 start-100 translate-middle\">{{ icon_info }}</span></button></a>"
C3: term | D3: - | E3: Absolute abundance / Population size | G3: surv_guide_meta | H3: objective | I3: obj_abundance | J3: =IF(D3<>"-",I3&"_"&D3,I3) -> obj_abundance | K3: Absolute abundance / Population size | L3: =IF(VLOOKUP(J3,find_replace!H:H,1,"false")=J3,"TRUE","FALSE") -> TRUE | M3: The number of individuals in a population ({{ rtxt_wearn_gloverkapfer_2017 }}). | N3: The number of individuals in a population (Wearn & Glover-Kapfer, 2017). | O3: =IF(M3=999,"",(" term_"&J3&": """&K3&"""")) -> term_obj_abundance: "Absolute abundance / Population size" | P3: =IF(M3="-","-",(" def_"&J3&": """&M3&"""")) -> def_obj_abundance: "The number of individuals in a population ({{ rtxt_wearn_gloverkapfer_2017 }})." | U3: xx | V3: \" target=\"_blank\" data-bs-toggle=\"tooltip\" data-bs-title=\" | W3: \"> | X3: <button type=\"button\" class=\"btn btn-bd-tip-info-hidden btn-sm position-relative\">.<span class=\"position-absolute top-0 start-100 translate-middle\">{{ icon_info }}</span></button></a> | Y3: =IF(M3<>"-",(" "&J3&"_ti"&": "&""""&"<a href=\"&""""&"09_glossary.html#"&J3&V3&K3&": "&M3&W3&""&X3&""""),"-") -> obj_abundance_ti: "<a href=\"09_glossary.html#obj_abundance\" target=\"_blank\" data-bs-toggle=\"tooltip\" data-bs-title=\"Absolute abundance / Population size: The number of individuals in a population ({{ rtxt_wearn_gloverkapfer_2017 }}).\"><button type=\"button\" class=\"btn btn-bd-tip-info-hidden btn-sm position-relative\">.<span class=\"position-absolute top-0 start-100 translate-middle\">{{ icon_info }}</span></button></a>"
B4: 1 | C4: field | D4: - | E4: ***Access Method** | F4: upper | G4: surv_guide_meta | H4: cam_visit | I4: access_method | J4: =IF(D4<>"-",I4&"_"&D4,I4) -> access_method | K4: Access Method | L4: =IF(VLOOKUP(J4,find_replace!H:H,1,"false")=J4,"TRUE","FALSE") -> TRUE | M4: The method used to reach the camera location (e.g., on 'Foot,' 'ATV,' 'Helicopter,' etc.). | N4: The method used to reach the camera location (e.g., on 'Foot,' 'ATV,' 'Helicopter,' etc.). | O4: =IF(M4=999,"",(" term_"&J4&": """&K4&"""")) -> term_access_method: "Access Method" | P4: =IF(M4="-","-",(" def_"&J4&": """&M4&"""")) -> def_access_method: "The method used to reach the camera location (e.g., on 'Foot,' 'ATV,' 'Helicopter,' etc.)." | R4: FALSE | S4: TRUE | T4: TRUE | U4: xx | V4: \" target=\"_blank\" data-bs-toggle=\"tooltip\" data-bs-title=\" | W4: \"> | X4: <button type=\"button\" class=\"btn btn-bd-tip-info-hidden btn-sm position-relative\">.<span class=\"position-absolute top-0 start-100 translate-middle\">{{ icon_info }}</span></button></a> | Y4: =IF(M4<>"-",(" "&J4&"_ti"&": "&""""&"<a href=\"&""""&"09_glossary.html#"&J4&V4&K4&": "&M4&W4&""&X4&""""),"-") -> access_method_ti: "<a href=\"09_glossary.html#access_method\" target=\"_blank\" data-bs-toggle=\"tooltip\" data-bs-title=\"Access Method: The method used to reach the camera location (e.g., on 'Foot,' 'ATV,' 'Helicopter,' etc.).\"><button type=\"button\" class=\"btn btn-bd-tip-info-hidden btn-sm position-relative\">.<span class=\"position-absolute top-0 start-100 translate-middle\">{{ icon_info }}</span></button></a>"
C5: term | D5: - | G5: clarke_et_al_2023 | I5: accuracy | J5: =IF(D5<>"-",I5&"_"&D5,I5) -> accuracy | K5: Accuracy | L5: =IF(VLOOKUP(J5,find_replace!H:H,1,"false")=J5,"TRUE","FALSE") -> TRUE | M5: How close a measured or estimated value is to the true value' ({{ rtxt_clarke_et_al_2023 }}). | N5: How close a measured or estimated value is to the true value' (Clarke et al., 2023). | O5: =IF(M5=999,"",(" term_"&J5&": """&K5&"""")) -> term_accuracy: "Accuracy" | P5: =IF(M5="-","-",(" def_"&J5&": """&M5&"""")) -> def_accuracy: "How close a measured or estimated value is to the true value' ({{ rtxt_clarke_et_al_2023 }})." | U5: xx | V5: \" target=\"_blank\" data-bs-toggle=\"tooltip\" data-bs-title=\" | W5: \"> | X5: <button type=\"button\" class=\"btn btn-bd-tip-info-hidden btn-sm position-relative\">.<span class=\"position-absolute top-0 start-100 translate-middle\">{{ icon_info }}</span></button></a> | Y5: =IF(M5<>"-",(" "&J5&"_ti"&": "&""""&"<a href=\"&""""&"09_glossary.html#"&J5&V5&K5&": "&M5&W5&""&X5&""""),"-") -> accuracy_ti: "<a href=\"09_glossary.html#accuracy\" target=\"_blank\" data-bs-toggle=\"tooltip\" data-bs-title=\"Accuracy: How close a measured or estimated value is to the true value' ({{ rtxt_clarke_et_al_2023 }}).\"><button type=\"button\" class=\"btn btn-bd-tip-info-hidden btn-sm position-relative\">.<span class=\"position-absolute top-0 start-100 translate-middle\">{{ icon_info }}</span></button></a>"
B6: 2 | C6: field_option | D6: - | E6: **Adult** | F6: upper | G6: surv_guide_meta | H6: img_processing | I6: age_class_adult | J6: =IF(D6<>"-",I6&"_"&D6,I6) -> age_class_adult | K6: Adult | L6: =IF(VLOOKUP(J6,find_replace!H:H,1,"false")=J6,"TRUE","FALSE") -> TRUE | M6: Animals that are old enough to breed; reproductively mature. | N6: Animals that are old enough to breed; reproductively mature. | O6: =IF(M6=999,"",(" term_"&J6&": """&K6&"""")) -> term_age_class_adult: "Adult" | P6: =IF(M6="-","-",(" def_"&J6&": """&M6&"""")) -> def_age_class_adult: "Animals that are old enough to breed; reproductively mature." | R6: NULL | S6: TRUE | T6: FALSE | U6: xx | V6: \" target=\"_blank\" data-bs-toggle=\"tooltip\" data-bs-title=\" | W6: \"> | X6: <button type=\"button\" class=\"btn btn-bd-tip-info-hidden btn-sm position-relative\">.<span class=\"position-absolute top-0 start-100 translate-middle\">{{ icon_info }}</span></button></a> | Y6: =IF(M6<>"-",(" "&J6&"_ti"&": "&""""&"<a href=\"&""""&"09_glossary.html#"&J6&V6&K6&": "&M6&W6&""&X6&""""),"-") -> age_class_adult_ti: "<a href=\"09_glossary.html#age_class_adult\" target=\"_blank\" data-bs-toggle=\"tooltip\" data-bs-title=\"Adult: Animals that are old enough to breed; reproductively mature.\"><button type=\"button\" class=\"btn btn-bd-tip-info-hidden btn-sm position-relative\">.<span class=\"position-absolute top-0 start-100 translate-middle\">{{ icon_info }}</span></button></a>"
B7: 3 | C7: field | D7: - | E7: **Age Class** | F7: upper | G7: surv_guide_meta | H7: img_processing | I7: age_class | J7: =IF(D7<>"-",I7&"_"&D7,I7) -> age_class | K7: Age Class | L7: =IF(VLOOKUP(J7,find_replace!H:H,1,"false")=J7,"TRUE","FALSE") -> TRUE | M7: The age classification of individual(s) being categorized (e.g., 'Adult,' 'Juvenile,' 'Subadult,' 'Subadult - Young of Year,' 'Subadult - Yearling,' or 'Unknown'). | N7: The age classification of individual(s) being categorized (e.g., 'Adult,' 'Juvenile,' 'Subadult,' 'Subadult - Young of Year,' 'Subadult - Yearling,' or 'Unknown'). | O7: =IF(M7=999,"",(" term_"&J7&": """&K7&"""")) -> term_age_class: "Age Class" | P7: =IF(M7="-","-",(" def_"&J7&": """&M7&"""")) -> def_age_class: "The age classification of individual(s) being categorized (e.g., 'Adult,' 'Juvenile,' 'Subadult,' 'Subadult - Young of Year,' 'Subadult - Yearling,' or 'Unknown'). " | R7: TRUE | S7: TRUE | T7: TRUE | U7: xx | V7: \" target=\"_blank\" data-bs-toggle=\"tooltip\" data-bs-title=\" | W7: \"> | X7: <button type=\"button\" class=\"btn btn-bd-tip-info-hidden btn-sm position-relative\">.<span class=\"position-absolute top-0 start-100 translate-middle\">{{ icon_info }}</span></button></a> | Y7: =IF(M7<>"-",(" "&J7&"_ti"&": "&""""&"<a href=\"&""""&"09_glossary.html#"&J7&V7&K7&": "&M7&W7&""&X7&""""),"-") -> age_class_ti: "<a href=\"09_glossary.html#age_class\" target=\"_blank\" data-bs-toggle=\"tooltip\" data-bs-title=\"Age Class: The age classification of individual(s) being categorized (e.g., 'Adult,' 'Juvenile,' 'Subadult,' 'Subadult - Young of Year,' 'Subadult - Yearling,' or 'Unknown'). \"><button type=\"button\" class=\"btn btn-bd-tip-info-hidden btn-sm position-relative\">.<span class=\"position-absolute top-0 start-100 translate-middle\">{{ icon_info }}</span></button></a>"
A8: NEW | C8: term | D8: - | E8: Alpha richness (α) | G8: surv_guide_meta | H8: objective_approach | I8: mod_divers_rich_alpha | J8: =IF(D8<>"-",I8&"_"&D8,I8) -> mod_divers_rich_alpha | K8: Alpha richness (α) | L8: =IF(VLOOKUP(J8,find_replace!H:H,1,"false")=J8,"TRUE","FALSE") -> TRUE | M8: The number of species at the level of an individual camera location ({{ rtxt_wearn_gloverkapfer_2017 }}). | N8: The number of species at the level of an individual camera location (Wearn & Glover-Kapfer, 2017). | O8: =IF(M8=999,"",(" term_"&J8&": """&K8&"""")) -> term_mod_divers_rich_alpha: "Alpha richness (α)" | P8: =IF(M8="-","-",(" def_"&J8&": """&M8&"""")) -> def_mod_divers_rich_alpha: "The number of species at the level of an individual camera location ({{ rtxt_wearn_gloverkapfer_2017 }})." | U8: xx | V8: \" target=\"_blank\" data-bs-toggle=\"tooltip\" data-bs-title=\" | W8: \"> | X8: <button type=\"button\" class=\"btn btn-bd-tip-info-hidden btn-sm position-relative\">.<span class=\"position-absolute top-0 start-100 translate-middle\">{{ icon_info }}</span></button></a> | Y8: =IF(M8<>"-",(" "&J8&"_ti"&": "&""""&"<a href=\"&""""&"09_glossary.html#"&J8&V8&K8&": "&M8&W8&""&X8&""""),"-") -> mod_divers_rich_alpha_ti: "<a href=\"09_glossary.html#mod_divers_rich_alpha\" target=\"_blank\" data-bs-toggle=\"tooltip\" data-bs-title=\"Alpha richness (α): The number of species at the level of an individual camera location ({{ rtxt_wearn_gloverkapfer_2017 }}).\"><button type=\"button\" class=\"btn btn-bd-tip-info-hidden btn-sm position-relative\">.<span class=\"position-absolute top-0 start-100 translate-middle\">{{ icon_info }}</span></button></a>"
B9: 4 | C9: field | D9: - | E9: **Analyst** | F9: upper | G9: surv_guide_meta | H9: img_processing | I9: analyst | J9: =IF(D9<>"-",I9&"_"&D9,I9) -> analyst | K9: Analyst | L9: =IF(VLOOKUP(J9,find_replace!H:H,1,"false")=J9,"TRUE","FALSE") -> TRUE | M9: The first and last names of the individual who provided the observation data point (species identification and associated information). If there are multiple analysts for an observation, enter the primary analyst. | N9: The first and last names of the individual who provided the observation data point (species identification and associated information). If there are multiple analysts for an observation, enter the primary analyst. | O9: =IF(M9=999,"",(" term_"&J9&": """&K9&"""")) -> term_analyst: "Analyst" | P9: =IF(M9="-","-",(" def_"&J9&": """&M9&"""")) -> def_analyst: "The first and last names of the individual who provided the observation data point (species identification and associated information). If there are multiple analysts for an observation, enter the primary analyst." | R9: TRUE | S9: TRUE | T9: TRUE | U9: xx | V9: \" target=\"_blank\" data-bs-toggle=\"tooltip\" data-bs-title=\" | W9: \"> | X9: <button type=\"button\" class=\"btn btn-bd-tip-info-hidden btn-sm position-relative\">.<span class=\"position-absolute top-0 start-100 translate-middle\">{{ icon_info }}</span></button></a> | Y9: =IF(M9<>"-",(" "&J9&"_ti"&": "&""""&"<a href=\"&""""&"09_glossary.html#"&J9&V9&K9&": "&M9&W9&""&X9&""""),"-") -> analyst_ti: "<a href=\"09_glossary.html#analyst\" target=\"_blank\" data-bs-toggle=\"tooltip\" data-bs-title=\"Analyst: The first and last names of the individual who provided the observation data point (species identification and associated information). If there are multiple analysts for an observation, enter the primary analyst.\"><button type=\"button\" class=\"btn btn-bd-tip-info-hidden btn-sm position-relative\">.<span class=\"position-absolute top-0 start-100 translate-middle\">{{ icon_info }}</span></button></a>"
B10: 5 | C10: field | D10: - | E10: ***Animal ID** | F10: upper | G10: surv_guide_meta | H10: img_processing | I10: animal_id | J10: =IF(D10<>"-",I10&"_"&D10,I10) -> animal_id | K10: Animal ID | L10: =IF(VLOOKUP(J10,find_replace!H:H,1,"false")=J10,"TRUE","FALSE") -> TRUE | M10: A unique ID for an animal that can be uniquely identified (e.g., marked in some way). If multiple unique individuals are identified, enter an Animal ID for each as a unique row. Leave blank if not applicable. | N10: A unique ID for an animal that can be uniquely identified (e.g., marked in some way). If multiple unique individuals are identified, enter an Animal ID for each as a unique row. Leave blank if not applicable. | O10: =IF(M10=999,"",(" term_"&J10&": """&K10&"""")) -> term_animal_id: "Animal ID" | P10: =IF(M10="-","-",(" def_"&J10&": """&M10&"""")) -> def_animal_id: "A unique ID for an animal that can be uniquely identified (e.g., marked in some way). If multiple unique individuals are identified, enter an Animal ID for each as a unique row. Leave blank if not applicable." | Q10: TRUE | R10: FALSE | S10: TRUE | T10: FALSE | U10: xx | V10: \" target=\"_blank\" data-bs-toggle=\"tooltip\" data-bs-title=\" | W10: \"> | X10: <button type=\"button\" class=\"btn btn-bd-tip-info-hidden btn-sm position-relative\">.<span class=\"position-absolute top-0 start-100 translate-middle\">{{ icon_info }}</span></button></a> | Y10: =IF(M10<>"-",(" "&J10&"_ti"&": "&""""&"<a href=\"&""""&"09_glossary.html#"&J10&V10&K10&": "&M10&W10&""&X10&""""),"-") -> animal_id_ti: "<a href=\"09_glossary.html#animal_id\" target=\"_blank\" data-bs-toggle=\"tooltip\" data-bs-title=\"Animal ID: A unique ID for an animal that can be uniquely identified (e.g., marked in some way). If multiple unique individuals are identified, enter an Animal ID for each as a unique row. Leave blank if not applicable.\"><button type=\"button\" class=\"btn btn-bd-tip-info-hidden btn-sm position-relative\">.<span class=\"position-absolute top-0 start-100 translate-middle\">{{ icon_info }}</span></button></a>"
B11: 6 | C11: term | D11: - | E11: Audible lure | G11: surv_guide_meta | H11: baitlure | I11: baitlure_audible_lure | J11: =IF(D11<>"-",I11&"_"&D11,I11) -> baitlure_audible_lure | K11: Audible lure | L11: =IF(VLOOKUP(J11,find_replace!H:H,1,"false")=J11,"TRUE","FALSE") -> TRUE | M11: Sounds imitating noises of prey or conspecifics that draw animals closer by eliciting curiosity ({{ rtxt_schlexer_2008 }}). | N11: Sounds imitating noises of prey or conspecifics that draw animals closer by eliciting curiosity (Schlexer, 2008). | O11: =IF(M11=999,"",(" term_"&J11&": """&K11&"""")) -> term_baitlure_audible_lure: "Audible lure" | P11: =IF(M11="-","-",(" def_"&J11&": """&M11&"""")) -> def_baitlure_audible_lure: "Sounds imitating noises of prey or conspecifics that draw animals closer by eliciting curiosity ({{ rtxt_schlexer_2008 }})." | R11: NULL | S11: FALSE | T11: TRUE | U11: xx | V11: \" target=\"_blank\" data-bs-toggle=\"tooltip\" data-bs-title=\" | W11: \"> | X11: <button type=\"button\" class=\"btn btn-bd-tip-info-hidden btn-sm position-relative\">.<span class=\"position-absolute top-0 start-100 translate-middle\">{{ icon_info }}</span></button></a> | Y11: =IF(M11<>"-",(" "&J11&"_ti"&": "&""""&"<a href=\"&""""&"09_glossary.html#"&J11&V11&K11&": "&M11&W11&""&X11&""""),"-") -> baitlure_audible_lure_ti: "<a href=\"09_glossary.html#baitlure_audible_lure\" target=\"_blank\" data-bs-toggle=\"tooltip\" data-bs-title=\"Audible lure: Sounds imitating noises of prey or conspecifics that draw animals closer by eliciting curiosity ({{ rtxt_schlexer_2008 }}).\"><button type=\"button\" class=\"btn btn-bd-tip-info-hidden btn-sm position-relative\">.<span class=\"position-absolute top-0 start-100 translate-middle\">{{ icon_info }}</span></button></a>"
B12: 7 | C12: term | D12: - | E12: Bait | G12: surv_guide_meta | H12: baitlure | I12: baitlure_bait | J12: =IF(D12<>"-",I12&"_"&D12,I12) -> baitlure_bait | K12: Bait | L12: =IF(VLOOKUP(J12,find_replace!H:H,1,"false")=J12,"TRUE","FALSE") -> TRUE | M12: A food item (or other substance) that is placed to attract animals via the sense of taste and olfactory cues ({{ rtxt_schlexer_2008 }}). | N12: A food item (or other substance) that is placed to attract animals via the sense of taste and olfactory cues (Schlexer, 2008). | O12: =IF(M12=999,"",(" term_"&J12&": """&K12&"""")) -> term_baitlure_bait: "Bait" | P12: =IF(M12="-","-",(" def_"&J12&": """&M12&"""")) -> def_baitlure_bait: "A food item (or other substance) that is placed to attract animals via the sense of taste and olfactory cues ({{ rtxt_schlexer_2008 }})." | R12: NULL | S12: TRUE | T12: TRUE | U12: xx | V12: \" target=\"_blank\" data-bs-toggle=\"tooltip\" data-bs-title=\" | W12: \"> | X12: <button type=\"button\" class=\"btn btn-bd-tip-info-hidden btn-sm position-relative\">.<span class=\"position-absolute top-0 start-100 translate-middle\">{{ icon_info }}</span></button></a> | Y12: =IF(M12<>"-",(" "&J12&"_ti"&": "&""""&"<a href=\"&""""&"09_glossary.html#"&J12&V12&K12&": "&M12&W12&""&X12&""""),"-") -> baitlure_bait_ti: "<a href=\"09_glossary.html#baitlure_bait\" target=\"_blank\" data-bs-toggle=\"tooltip\" data-bs-title=\"Bait: A food item (or other substance) that is placed to attract animals via the sense of taste and olfactory cues ({{ rtxt_schlexer_2008 }}).\"><button type=\"button\" class=\"btn btn-bd-tip-info-hidden btn-sm position-relative\">.<span class=\"position-absolute top-0 start-100 translate-middle\">{{ icon_info }}</span></button></a>"
B13: 8 | C13: field | D13: - | E13: **Bait*/Lure Type** | F13: upper | G13: surv_guide_meta | H13: baitlure | I13: baitlure_bait_lure_type | J13: =IF(D13<>"-",I13&"_"&D13,I13) -> baitlure_bait_lure_type | K13: Bait/Lure Type | L13: =IF(VLOOKUP(J13,find_replace!H:H,1,"false")=J13,"TRUE","FALSE") -> TRUE | M13: The type of bait or lure used at a camera location. Record 'None' if a Bait*/Lure Type was not used and 'Unknown' if not known. If 'Other,' describe in the Deployment Comments. | N13: The type of bait or lure used at a camera location. Record 'None' if a Bait*/Lure Type was not used and 'Unknown' if not known. If 'Other,' describe in the Deployment Comments. | O13: =IF(M13=999,"",(" term_"&J13&": """&K13&"""")) -> term_baitlure_bait_lure_type: "Bait/Lure Type" | P13: =IF(M13="-","-",(" def_"&J13&": """&M13&"""")) -> def_baitlure_bait_lure_type: "The type of bait or lure used at a camera location. Record 'None' if a Bait*/Lure Type was not used and 'Unknown' if not known. If 'Other,' describe in the Deployment Comments." | Q13: TRUE | R13: TRUE | S13: TRUE | T13: TRUE | U13: xx | V13: \" target=\"_blank\" data-bs-toggle=\"tooltip\" data-bs-title=\" | W13: \"> | X13: <button type=\"button\" class=\"btn btn-bd-tip-info-hidden btn-sm position-relative\">.<span class=\"position-absolute top-0 start-100 translate-middle\">{{ icon_info }}</span></button></a> | Y13: =IF(M13<>"-",(" "&J13&"_ti"&": "&""""&"<a href=\"&""""&"09_glossary.html#"&J13&V13&K13&": "&M13&W13&""&X13&""""),"-") -> baitlure_bait_lure_type_ti: "<a href=\"09_glossary.html#baitlure_bait_lure_type\" target=\"_blank\" data-bs-toggle=\"tooltip\" data-bs-title=\"Bait/Lure Type: The type of bait or lure used at a camera location. Record 'None' if a Bait*/Lure Type was not used and 'Unknown' if not known. If 'Other,' describe in the Deployment Comments.\"><button type=\"button\" class=\"btn btn-bd-tip-info-hidden btn-sm position-relative\">.<span class=\"position-absolute top-0 start-100 translate-middle\">{{ icon_info }}</span></button></a>"
B14: 9 | C14: field | D14: - | E14: ***Batteries Replaced** | F14: upper | G14: surv_guide_meta | H14: cam_visit_equip | I14: batteries_replaced | J14: =IF(D14<>"-",I14&"_"&D14,I14) -> batteries_replaced | K14: Batteries Replaced | L14: =IF(VLOOKUP(J14,find_replace!H:H,1,"false")=J14,"TRUE","FALSE") -> TRUE | M14: Whether the camera's batteries were replaced. | N14: Whether the camera's batteries were replaced. | O14: =IF(M14=999,"",(" term_"&J14&": """&K14&"""")) -> term_batteries_replaced: "Batteries Replaced" | P14: =IF(M14="-","-",(" def_"&J14&": """&M14&"""")) -> def_batteries_replaced: "Whether the camera's batteries were replaced." | R14: FALSE | S14: TRUE | T14: TRUE | U14: xx | V14: \" target=\"_blank\" data-bs-toggle=\"tooltip\" data-bs-title=\" | W14: \"> | X14: <button type=\"button\" class=\"btn btn-bd-tip-info-hidden btn-sm position-relative\">.<span class=\"position-absolute top-0 start-100 translate-middle\">{{ icon_info }}</span></button></a> | Y14: =IF(M14<>"-",(" "&J14&"_ti"&": "&""""&"<a href=\"&""""&"09_glossary.html#"&J14&V14&K14&": "&M14&W14&""&X14&""""),"-") -> batteries_replaced_ti: "<a href=\"09_glossary.html#batteries_replaced\" target=\"_blank\" data-bs-toggle=\"tooltip\" data-bs-title=\"Batteries Replaced: Whether the camera's batteries were replaced.\"><button type=\"button\" class=\"btn btn-bd-tip-info-hidden btn-sm position-relative\">.<span class=\"position-absolute top-0 start-100 translate-middle\">{{ icon_info }}</span></button></a>"
C15: term | D15: - | E15: Behaviour | G15: surv_guide_meta | H15: objective | I15: obj_behaviour | J15: =IF(D15<>"-",I15&"_"&D15,I15) -> obj_behaviour | K15: Behaviour | L15: =IF(VLOOKUP(J15,find_replace!H:H,1,"false")=J15,"TRUE","FALSE") -> TRUE | M15: Behaviour focused objectives vary greatly; they may be qualitative or quantitative (e.g., diel activity patterns, mating, boldness, predation, foraging, activity patterns, vigilance, parental care ({{ rtxt_caravaggi_et_al_2020 }}; {{ rtxt_wearn_gloverkapfer_2017 }}). | N15: Behaviour focused objectives vary greatly; they may be qualitative or quantitative (e.g., diel activity patterns, mating, boldness, predation, foraging, activity patterns, vigilance, parental care (Caravaggi et al., 2020; Wearn & Glover-Kapfer, 2017). | O15: =IF(M15=999,"",(" term_"&J15&": """&K15&"""")) -> term_obj_behaviour: "Behaviour" | P15: =IF(M15="-","-",(" def_"&J15&": """&M15&"""")) -> def_obj_behaviour: "Behaviour focused objectives vary greatly; they may be qualitative or quantitative (e.g., diel activity patterns, mating, boldness, predation, foraging, activity patterns, vigilance, parental care ({{ rtxt_caravaggi_et_al_2020 }}; {{ rtxt_wearn_gloverkapfer_2017 }})." | U15: xx | V15: \" target=\"_blank\" data-bs-toggle=\"tooltip\" data-bs-title=\" | W15: \"> | X15: <button type=\"button\" class=\"btn btn-bd-tip-info-hidden btn-sm position-relative\">.<span class=\"position-absolute top-0 start-100 translate-middle\">{{ icon_info }}</span></button></a> | Y15: =IF(M15<>"-",(" "&J15&"_ti"&": "&""""&"<a href=\"&""""&"09_glossary.html#"&J15&V15&K15&": "&M15&W15&""&X15&""""),"-") -> obj_behaviour_ti: "<a href=\"09_glossary.html#obj_behaviour\" target=\"_blank\" data-bs-toggle=\"tooltip\" data-bs-title=\"Behaviour: Behaviour focused objectives vary greatly; they may be qualitative or quantitative (e.g., diel activity patterns, mating, boldness, predation, foraging, activity patterns, vigilance, parental care ({{ rtxt_caravaggi_et_al_2020 }}; {{ rtxt_wearn_gloverkapfer_2017 }}).\"><button type=\"button\" class=\"btn btn-bd-tip-info-hidden btn-sm position-relative\">.<span class=\"position-absolute top-0 start-100 translate-middle\">{{ icon_info }}</span></button></a>"
B16: 10 | C16: field | D16: tag | E16: **\*Behaviour** | F16: upper | G16: surv_guide_meta | H16: cam_visit_equip | I16: behaviour | J16: =IF(D16<>"-",I16&"_"&D16,I16) -> behaviour_tag | K16: Behaviour (tag) | L16: =IF(VLOOKUP(J16,find_replace!H:H,1,"false")=J16,"TRUE","FALSE") -> #N/A | M16: The behaviour of the individual(s) being categorized (e.g., 'Standing,' 'Drinking,' 'Vigilant,' etc.). | N16: The behaviour of the individual(s) being categorized (e.g., 'Standing,' 'Drinking,' 'Vigilant,' etc.). | O16: =IF(M16=999,"",(" term_"&J16&": """&K16&"""")) -> term_behaviour_tag: "Behaviour (tag)" | P16: =IF(M16="-","-",(" def_"&J16&": """&M16&"""")) -> def_behaviour_tag: "The behaviour of the individual(s) being categorized (e.g., 'Standing,' 'Drinking,' 'Vigilant,' etc.)." | R16: FALSE | S16: TRUE | T16: TRUE | U16: xx | V16: \" target=\"_blank\" data-bs-toggle=\"tooltip\" data-bs-title=\" | W16: \"> | X16: <button type=\"button\" class=\"btn btn-bd-tip-info-hidden btn-sm position-relative\">.<span class=\"position-absolute top-0 start-100 translate-middle\">{{ icon_info }}</span></button></a> | Y16: =IF(M16<>"-",(" "&J16&"_ti"&": "&""""&"<a href=\"&""""&"09_glossary.html#"&J16&V16&K16&": "&M16&W16&""&X16&""""),"-") -> behaviour_tag_ti: "<a href=\"09_glossary.html#behaviour_tag\" target=\"_blank\" data-bs-toggle=\"tooltip\" data-bs-title=\"Behaviour (tag): The behaviour of the individual(s) being categorized (e.g., 'Standing,' 'Drinking,' 'Vigilant,' etc.).\"><button type=\"button\" class=\"btn btn-bd-tip-info-hidden btn-sm position-relative\">.<span class=\"position-absolute top-0 start-100 translate-middle\">{{ icon_info }}</span></button></a>"
A17: NEW | C17: term | D17: - | E17: Beta-diversity (β) | G17: surv_guide_meta | H17: objective_approach | I17: mod_divers_rich_beta | J17: =IF(D17<>"-",I17&"_"&D17,I17) -> mod_divers_rich_beta | K17: Beta-diversity (β) | L17: =IF(VLOOKUP(J17,find_replace!H:H,1,"false")=J17,"TRUE","FALSE") -> TRUE | M17: The differences between the communities or, more formally, the variance among the communities ({{ rtxt_wearn_gloverkapfer_2017 }}). | N17: The differences between the communities or, more formally, the variance among the communities (Wearn & Glover-Kapfer, 2017). | O17: =IF(M17=999,"",(" term_"&J17&": """&K17&"""")) -> term_mod_divers_rich_beta: "Beta-diversity (β)" | P17: =IF(M17="-","-",(" def_"&J17&": """&M17&"""")) -> def_mod_divers_rich_beta: "The differences between the communities or, more formally, the variance among the communities ({{ rtxt_wearn_gloverkapfer_2017 }})." | U17: xx | V17: \" target=\"_blank\" data-bs-toggle=\"tooltip\" data-bs-title=\" | W17: \"> | X17: <button type=\"button\" class=\"btn btn-bd-tip-info-hidden btn-sm position-relative\">.<span class=\"position-absolute top-0 start-100 translate-middle\">{{ icon_info }}</span></button></a> | Y17: =IF(M17<>"-",(" "&J17&"_ti"&": "&""""&"<a href=\"&""""&"09_glossary.html#"&J17&V17&K17&": "&M17&W17&""&X17&""""),"-") -> mod_divers_rich_beta_ti: "<a href=\"09_glossary.html#mod_divers_rich_beta\" target=\"_blank\" data-bs-toggle=\"tooltip\" data-bs-title=\"Beta-diversity (β): The differences between the communities or, more formally, the variance among the communities ({{ rtxt_wearn_gloverkapfer_2017 }}).\"><button type=\"button\" class=\"btn btn-bd-tip-info-hidden btn-sm position-relative\">.<span class=\"position-absolute top-0 start-100 translate-middle\">{{ icon_info }}</span></button></a>"
C18: term | D18: - | G18: kemp_et_al_2022 | I18: bias | J18: =IF(D18<>"-",I18&"_"&D18,I18) -> bias | K18: Bias | L18: =IF(VLOOKUP(J18,find_replace!H:H,1,"false")=J18,"TRUE","FALSE") -> TRUE | M18: A skewed or altered perspective. Biased data refers to data that may be inaccurate or unevenly portrayed (usually in favour of specific variables) and is therefore not as robust.' ({{ rtxt_kemp_et_al_2022 }}). | N18: A skewed or altered perspective. Biased data refers to data that may be inaccurate or unevenly portrayed (usually in favour of specific variables) and is therefore not as robust.' (Kemp et al., 2022). | O18: =IF(M18=999,"",(" term_"&J18&": """&K18&"""")) -> term_bias: "Bias" | P18: =IF(M18="-","-",(" def_"&J18&": """&M18&"""")) -> def_bias: "A skewed or altered perspective. Biased data refers to data that may be inaccurate or unevenly portrayed (usually in favour of specific variables) and is therefore not as robust.' ({{ rtxt_kemp_et_al_2022 }})." | U18: xx | V18: \" target=\"_blank\" data-bs-toggle=\"tooltip\" data-bs-title=\" | W18: \"> | X18: <button type=\"button\" class=\"btn btn-bd-tip-info-hidden btn-sm position-relative\">.<span class=\"position-absolute top-0 start-100 translate-middle\">{{ icon_info }}</span></button></a> | Y18: =IF(M18<>"-",(" "&J18&"_ti"&": "&""""&"<a href=\"&""""&"09_glossary.html#"&J18&V18&K18&": "&M18&W18&""&X18&""""),"-") -> bias_ti: "<a href=\"09_glossary.html#bias\" target=\"_blank\" data-bs-toggle=\"tooltip\" data-bs-title=\"Bias: A skewed or altered perspective. Biased data refers to data that may be inaccurate or unevenly portrayed (usually in favour of specific variables) and is therefore not as robust.' ({{ rtxt_kemp_et_al_2022 }}).\"><button type=\"button\" class=\"btn btn-bd-tip-info-hidden btn-sm position-relative\">.<span class=\"position-absolute top-0 start-100 translate-middle\">{{ icon_info }}</span></button></a>"
C19: term | D19: - | G19: kemp_et_al_2022 | I19: biodiversity | J19: =IF(D19<>"-",I19&"_"&D19,I19) -> biodiversity | K19: Biodiversity | L19: =IF(VLOOKUP(J19,find_replace!H:H,1,"false")=J19,"TRUE","FALSE") -> TRUE | M19: The variation of life in the natural world. In the context of this guide, biodiversity refers to the variety of different wildlife species found in an area.' ({{ rtxt_kemp_et_al_2022 }}). | N19: The variation of life in the natural world. In the context of this guide, biodiversity refers to the variety of different wildlife species found in an area.' (Kemp et al., 2022). | O19: =IF(M19=999,"",(" term_"&J19&": """&K19&"""")) -> term_biodiversity: "Biodiversity" | P19: =IF(M19="-","-",(" def_"&J19&": """&M19&"""")) -> def_biodiversity: "The variation of life in the natural world. In the context of this guide, biodiversity refers to the variety of different wildlife species found in an area.' ({{ rtxt_kemp_et_al_2022 }})." | U19: xx | V19: \" target=\"_blank\" data-bs-toggle=\"tooltip\" data-bs-title=\" | W19: \"> | X19: <button type=\"button\" class=\"btn btn-bd-tip-info-hidden btn-sm position-relative\">.<span class=\"position-absolute top-0 start-100 translate-middle\">{{ icon_info }}</span></button></a> | Y19: =IF(M19<>"-",(" "&J19&"_ti"&": "&""""&"<a href=\"&""""&"09_glossary.html#"&J19&V19&K19&": "&M19&W19&""&X19&""""),"-") -> biodiversity_ti: "<a href=\"09_glossary.html#biodiversity\" target=\"_blank\" data-bs-toggle=\"tooltip\" data-bs-title=\"Biodiversity: The variation of life in the natural world. In the context of this guide, biodiversity refers to the variety of different wildlife species found in an area.' ({{ rtxt_kemp_et_al_2022 }}).\"><button type=\"button\" class=\"btn btn-bd-tip-info-hidden btn-sm position-relative\">.<span class=\"position-absolute top-0 start-100 translate-middle\">{{ icon_info }}</span></button></a>"
C20: term | D20: - | G20: kemp_et_al_2022 | I20: obj_vital_rate_birth | J20: =IF(D20<>"-",I20&"_"&D20,I20) -> obj_vital_rate_birth | K20: Birth rate | L20: =IF(VLOOKUP(J20,find_replace!H:H,1,"false")=J20,"TRUE","FALSE") -> #N/A | M20: The average number of offspring produced per individual per unit time.' ({{ rtxt_nbckc_2024a }}) | N20: The average number of offspring produced per individual per unit time.' (NBCKC, 2024a) | O20: =IF(M20=999,"",(" term_"&J20&": """&K20&"""")) -> term_obj_vital_rate_birth: "Birth rate" | P20: =IF(M20="-","-",(" def_"&J20&": """&M20&"""")) -> def_obj_vital_rate_birth: "The average number of offspring produced per individual per unit time.' ({{ rtxt_nbckc_2024a }})" | U20: xx | V20: \" target=\"_blank\" data-bs-toggle=\"tooltip\" data-bs-title=\" | W20: \"> | X20: <button type=\"button\" class=\"btn btn-bd-tip-info-hidden btn-sm position-relative\">.<span class=\"position-absolute top-0 start-100 translate-middle\">{{ icon_info }}</span></button></a> | Y20: =IF(M20<>"-",(" "&J20&"_ti"&": "&""""&"<a href=\"&""""&"09_glossary.html#"&J20&V20&K20&": "&M20&W20&""&X20&""""),"-") -> obj_vital_rate_birth_ti: "<a href=\"09_glossary.html#obj_vital_rate_birth\" target=\"_blank\" data-bs-toggle=\"tooltip\" data-bs-title=\"Birth rate: The average number of offspring produced per individual per unit time.' ({{ rtxt_nbckc_2024a }})\"><button type=\"button\" class=\"btn btn-bd-tip-info-hidden btn-sm position-relative\">.<span class=\"position-absolute top-0 start-100 translate-middle\">{{ icon_info }}</span></button></a>"
B21: 11 | C21: field | D21: - | E21: **\*Camera Active On Arrival** | F21: upper | G21: surv_guide_meta | H21: cam_visit_equip | I21: cam_active_on_arrival | J21: =IF(D21<>"-",I21&"_"&D21,I21) -> cam_active_on_arrival | K21: Camera Active On Arrival | L21: =IF(VLOOKUP(J21,find_replace!H:H,1,"false")=J21,"TRUE","FALSE") -> TRUE | M21: Whether a camera was functional upon arrival. | N21: Whether a camera was functional upon arrival. | O21: =IF(M21=999,"",(" term_"&J21&": """&K21&"""")) -> term_cam_active_on_arrival: "Camera Active On Arrival" | P21: =IF(M21="-","-",(" def_"&J21&": """&M21&"""")) -> def_cam_active_on_arrival: "Whether a camera was functional upon arrival." | R21: FALSE | S21: TRUE | T21: TRUE | U21: xx | V21: \" target=\"_blank\" data-bs-toggle=\"tooltip\" data-bs-title=\" | W21: \"> | X21: <button type=\"button\" class=\"btn btn-bd-tip-info-hidden btn-sm position-relative\">.<span class=\"position-absolute top-0 start-100 translate-middle\">{{ icon_info }}</span></button></a> | Y21: =IF(M21<>"-",(" "&J21&"_ti"&": "&""""&"<a href=\"&""""&"09_glossary.html#"&J21&V21&K21&": "&M21&W21&""&X21&""""),"-") -> cam_active_on_arrival_ti: "<a href=\"09_glossary.html#cam_active_on_arrival\" target=\"_blank\" data-bs-toggle=\"tooltip\" data-bs-title=\"Camera Active On Arrival: Whether a camera was functional upon arrival.\"><button type=\"button\" class=\"btn btn-bd-tip-info-hidden btn-sm position-relative\">.<span class=\"position-absolute top-0 start-100 translate-middle\">{{ icon_info }}</span></button></a>"
B22: 12 | C22: field | D22: - | E22: **\*Camera Active On Departure** | F22: upper | G22: surv_guide_meta | H22: cam_visit_equip | I22: cam_active_on_departure | J22: =IF(D22<>"-",I22&"_"&D22,I22) -> cam_active_on_departure | K22: Camera Active On Departure | L22: =IF(VLOOKUP(J22,find_replace!H:H,1,"false")=J22,"TRUE","FALSE") -> TRUE | M22: Whether a camera was functional upon departure. | N22: Whether a camera was functional upon departure. | O22: =IF(M22=999,"",(" term_"&J22&": """&K22&"""")) -> term_cam_active_on_departure: "Camera Active On Departure" | P22: =IF(M22="-","-",(" def_"&J22&": """&M22&"""")) -> def_cam_active_on_departure: "Whether a camera was functional upon departure." | R22: FALSE | S22: TRUE | T22: TRUE | U22: xx | V22: \" target=\"_blank\" data-bs-toggle=\"tooltip\" data-bs-title=\" | W22: \"> | X22: <button type=\"button\" class=\"btn btn-bd-tip-info-hidden btn-sm position-relative\">.<span class=\"position-absolute top-0 start-100 translate-middle\">{{ icon_info }}</span></button></a> | Y22: =IF(M22<>"-",(" "&J22&"_ti"&": "&""""&"<a href=\"&""""&"09_glossary.html#"&J22&V22&K22&": "&M22&W22&""&X22&""""),"-") -> cam_active_on_departure_ti: "<a href=\"09_glossary.html#cam_active_on_departure\" target=\"_blank\" data-bs-toggle=\"tooltip\" data-bs-title=\"Camera Active On Departure: Whether a camera was functional upon departure.\"><button type=\"button\" class=\"btn btn-bd-tip-info-hidden btn-sm position-relative\">.<span class=\"position-absolute top-0 start-100 translate-middle\">{{ icon_info }}</span></button></a>"
B23: 13 | C23: term | D23: - | E23: Camera angle | G23: surv_guide_meta | H23: cam_visit_placement | I23: cam_angle | J23: =IF(D23<>"-",I23&"_"&D23,I23) -> cam_angle | K23: Camera angle | L23: =IF(VLOOKUP(J23,find_replace!H:H,1,"false")=J23,"TRUE","FALSE") -> TRUE | M23: The degree at which the camera is pointed toward the FOV Target Feature relative to the horizontal ground surface (with respect to slope, if applicable). | N23: The degree at which the camera is pointed toward the FOV Target Feature relative to the horizontal ground surface (with respect to slope, if applicable). | O23: =IF(M23=999,"",(" term_"&J23&": """&K23&"""")) -> term_cam_angle: "Camera angle" | P23: =IF(M23="-","-",(" def_"&J23&": """&M23&"""")) -> def_cam_angle: "The degree at which the camera is pointed toward the FOV Target Feature relative to the horizontal ground surface (with respect to slope, if applicable)." | R23: NULL | S23: FALSE | T23: TRUE | U23: xx | V23: \" target=\"_blank\" data-bs-toggle=\"tooltip\" data-bs-title=\" | W23: \"> | X23: <button type=\"button\" class=\"btn btn-bd-tip-info-hidden btn-sm position-relative\">.<span class=\"position-absolute top-0 start-100 translate-middle\">{{ icon_info }}</span></button></a> | Y23: =IF(M23<>"-",(" "&J23&"_ti"&": "&""""&"<a href=\"&""""&"09_glossary.html#"&J23&V23&K23&": "&M23&W23&""&X23&""""),"-") -> cam_angle_ti: "<a href=\"09_glossary.html#cam_angle\" target=\"_blank\" data-bs-toggle=\"tooltip\" data-bs-title=\"Camera angle: The degree at which the camera is pointed toward the FOV Target Feature relative to the horizontal ground surface (with respect to slope, if applicable).\"><button type=\"button\" class=\"btn btn-bd-tip-info-hidden btn-sm position-relative\">.<span class=\"position-absolute top-0 start-100 translate-middle\">{{ icon_info }}</span></button></a>"
B24: 14 | C24: field | D24: - | E24: **\*Camera Attachment** | F24: upper | G24: surv_guide_meta | H24: cam_visit_placement | I24: cam_attachment | J24: =IF(D24<>"-",I24&"_"&D24,I24) -> cam_attachment | K24: Camera Attachment | L24: =IF(VLOOKUP(J24,find_replace!H:H,1,"false")=J24,"TRUE","FALSE") -> TRUE | M24: The method*/tools used to attach the camera (e.g., attached to a tree with a bungee cord; reported as codes such as 'Tree + Bungee*/Strap'). If 'Other,' describe in the Camera Location Comments. | N24: The method*/tools used to attach the camera (e.g., attached to a tree with a bungee cord; reported as codes such as 'Tree + Bungee*/Strap'). If 'Other,' describe in the Camera Location Comments. | O24: =IF(M24=999,"",(" term_"&J24&": """&K24&"""")) -> term_cam_attachment: "Camera Attachment" | P24: =IF(M24="-","-",(" def_"&J24&": """&M24&"""")) -> def_cam_attachment: "The method*/tools used to attach the camera (e.g., attached to a tree with a bungee cord; reported as codes such as 'Tree + Bungee*/Strap'). If 'Other,' describe in the Camera Location Comments." | Q24: TRUE | R24: FALSE | S24: TRUE | T24: TRUE | U24: xx | V24: \" target=\"_blank\" data-bs-toggle=\"tooltip\" data-bs-title=\" | W24: \"> | X24: <button type=\"button\" class=\"btn btn-bd-tip-info-hidden btn-sm position-relative\">.<span class=\"position-absolute top-0 start-100 translate-middle\">{{ icon_info }}</span></button></a> | Y24: =IF(M24<>"-",(" "&J24&"_ti"&": "&""""&"<a href=\"&""""&"09_glossary.html#"&J24&V24&K24&": "&M24&W24&""&X24&""""),"-") -> cam_attachment_ti: "<a href=\"09_glossary.html#cam_attachment\" target=\"_blank\" data-bs-toggle=\"tooltip\" data-bs-title=\"Camera Attachment: The method*/tools used to attach the camera (e.g., attached to a tree with a bungee cord; reported as codes such as 'Tree + Bungee*/Strap'). If 'Other,' describe in the Camera Location Comments.\"><button type=\"button\" class=\"btn btn-bd-tip-info-hidden btn-sm position-relative\">.<span class=\"position-absolute top-0 start-100 translate-middle\">{{ icon_info }}</span></button></a>"
B25: 15 | C25: field | D25: - | E25: **\*Camera Damaged** | F25: upper | G25: surv_guide_meta | H25: cam_visit_equip | I25: cam_damaged | J25: =IF(D25<>"-",I25&"_"&D25,I25) -> cam_damaged | K25: Camera Damaged | L25: =IF(VLOOKUP(J25,find_replace!H:H,1,"false")=J25,"TRUE","FALSE") -> TRUE | M25: Whether the camera was damaged or malfunctioning; if there is any damage to the device (physical or mechanical), the crew should describe the damage in the Service*/Retrieval Comments. | N25: Whether the camera was damaged or malfunctioning; if there is any damage to the device (physical or mechanical), the crew should describe the damage in the Service*/Retrieval Comments. | O25: =IF(M25=999,"",(" term_"&J25&": """&K25&"""")) -> term_cam_damaged: "Camera Damaged" | P25: =IF(M25="-","-",(" def_"&J25&": """&M25&"""")) -> def_cam_damaged: "Whether the camera was damaged or malfunctioning; if there is any damage to the device (physical or mechanical), the crew should describe the damage in the Service*/Retrieval Comments." | R25: FALSE | S25: TRUE | T25: TRUE | U25: xx | V25: \" target=\"_blank\" data-bs-toggle=\"tooltip\" data-bs-title=\" | W25: \"> | X25: <button type=\"button\" class=\"btn btn-bd-tip-info-hidden btn-sm position-relative\">.<span class=\"position-absolute top-0 start-100 translate-middle\">{{ icon_info }}</span></button></a> | Y25: =IF(M25<>"-",(" "&J25&"_ti"&": "&""""&"<a href=\"&""""&"09_glossary.html#"&J25&V25&K25&": "&M25&W25&""&X25&""""),"-") -> cam_damaged_ti: "<a href=\"09_glossary.html#cam_damaged\" target=\"_blank\" data-bs-toggle=\"tooltip\" data-bs-title=\"Camera Damaged: Whether the camera was damaged or malfunctioning; if there is any damage to the device (physical or mechanical), the crew should describe the damage in the Service*/Retrieval Comments.\"><button type=\"button\" class=\"btn btn-bd-tip-info-hidden btn-sm position-relative\">.<span class=\"position-absolute top-0 start-100 translate-middle\">{{ icon_info }}</span></button></a>"
B26: 16 | C26: term | D26: - | E26: Camera days per camera location | G26: surv_guide_meta | H26: sampledesign | I26: cam_days_per_cam_location | J26: =IF(D26<>"-",I26&"_"&D26,I26) -> cam_days_per_cam_location | K26: Camera days per camera location | L26: =IF(VLOOKUP(J26,find_replace!H:H,1,"false")=J26,"TRUE","FALSE") -> TRUE | M26: The number of days each camera was active and functioning during the period it was deployed (e.g., 24-hour periods or the difference in days between the Deployment Start Date Time and the Deployment End Date Time if there were no interruptions). | N26: The number of days each camera was active and functioning during the period it was deployed (e.g., 24-hour periods or the difference in days between the Deployment Start Date Time and the Deployment End Date Time if there were no interruptions). | O26: =IF(M26=999,"",(" term_"&J26&": """&K26&"""")) -> term_cam_days_per_cam_location: "Camera days per camera location" | P26: =IF(M26="-","-",(" def_"&J26&": """&M26&"""")) -> def_cam_days_per_cam_location: "The number of days each camera was active and functioning during the period it was deployed (e.g., 24-hour periods or the difference in days between the Deployment Start Date Time and the Deployment End Date Time if there were no interruptions)." | R26: NULL | S26: FALSE | T26: TRUE | U26: xx | V26: \" target=\"_blank\" data-bs-toggle=\"tooltip\" data-bs-title=\" | W26: \"> | X26: <button type=\"button\" class=\"btn btn-bd-tip-info-hidden btn-sm position-relative\">.<span class=\"position-absolute top-0 start-100 translate-middle\">{{ icon_info }}</span></button></a> | Y26: =IF(M26<>"-",(" "&J26&"_ti"&": "&""""&"<a href=\"&""""&"09_glossary.html#"&J26&V26&K26&": "&M26&W26&""&X26&""""),"-") -> cam_days_per_cam_location_ti: "<a href=\"09_glossary.html#cam_days_per_cam_location\" target=\"_blank\" data-bs-toggle=\"tooltip\" data-bs-title=\"Camera days per camera location: The number of days each camera was active and functioning during the period it was deployed (e.g., 24-hour periods or the difference in days between the Deployment Start Date Time and the Deployment End Date Time if there were no interruptions).\"><button type=\"button\" class=\"btn btn-bd-tip-info-hidden btn-sm position-relative\">.<span class=\"position-absolute top-0 start-100 translate-middle\">{{ icon_info }}</span></button></a>"
B27: 17 | C27: field | D27: - | E27: **\*Camera Direction (degrees)** | F27: upper | G27: surv_guide_meta | H27: cam_visit_placement | I27: cam_direction | J27: =IF(D27<>"-",I27&"_"&D27,I27) -> cam_direction | K27: Camera Direction (degrees) | L27: =IF(VLOOKUP(J27,find_replace!H:H,1,"false")=J27,"TRUE","FALSE") -> TRUE | M27: The cardinal direction that a camera faces. Ideally, cameras should face north (N; i.e. '0' degrees), or south (S; i.e. '180' degrees) if north is not possible. The Camera Direction should be chosen to ensure the field of view (FOV) is of the original FOV target feature. | N27: The cardinal direction that a camera faces. Ideally, cameras should face north (N; i.e. '0' degrees), or south (S; i.e. '180' degrees) if north is not possible. The Camera Direction should be chosen to ensure the field of view (FOV) is of the original FOV target feature. | O27: =IF(M27=999,"",(" term_"&J27&": """&K27&"""")) -> term_cam_direction: "Camera Direction (degrees)" | P27: =IF(M27="-","-",(" def_"&J27&": """&M27&"""")) -> def_cam_direction: "The cardinal direction that a camera faces. Ideally, cameras should face north (N; i.e. '0' degrees), or south (S; i.e. '180' degrees) if north is not possible. The Camera Direction should be chosen to ensure the field of view (FOV) is of the original FOV target feature." | R27: FALSE | S27: TRUE | T27: TRUE | U27: xx | V27: \" target=\"_blank\" data-bs-toggle=\"tooltip\" data-bs-title=\" | W27: \"> | X27: <button type=\"button\" class=\"btn btn-bd-tip-info-hidden btn-sm position-relative\">.<span class=\"position-absolute top-0 start-100 translate-middle\">{{ icon_info }}</span></button></a> | Y27: =IF(M27<>"-",(" "&J27&"_ti"&": "&""""&"<a href=\"&""""&"09_glossary.html#"&J27&V27&K27&": "&M27&W27&""&X27&""""),"-") -> cam_direction_ti: "<a href=\"09_glossary.html#cam_direction\" target=\"_blank\" data-bs-toggle=\"tooltip\" data-bs-title=\"Camera Direction (degrees): The cardinal direction that a camera faces. Ideally, cameras should face north (N; i.e. '0' degrees), or south (S; i.e. '180' degrees) if north is not possible. The Camera Direction should be chosen to ensure the field of view (FOV) is of the original FOV target feature.\"><button type=\"button\" class=\"btn btn-bd-tip-info-hidden btn-sm position-relative\">.<span class=\"position-absolute top-0 start-100 translate-middle\">{{ icon_info }}</span></button></a>"
B28: 18 | C28: field | D28: - | E28: **Camera Height (m) ** | F28: upper | G28: surv_guide_meta | H28: cam_visit_placement | I28: cam_height | J28: =IF(D28<>"-",I28&"_"&D28,I28) -> cam_height | K28: Camera Height (m) | L28: =IF(VLOOKUP(J28,find_replace!H:H,1,"false")=J28,"TRUE","FALSE") -> TRUE | M28: The height from the ground (below snow) to the bottom of the lens (metres; to the nearest 0.05 m). | N28: The height from the ground (below snow) to the bottom of the lens (metres; to the nearest 0.05 m). | O28: =IF(M28=999,"",(" term_"&J28&": """&K28&"""")) -> term_cam_height: "Camera Height (m)" | P28: =IF(M28="-","-",(" def_"&J28&": """&M28&"""")) -> def_cam_height: "The height from the ground (below snow) to the bottom of the lens (metres; to the nearest 0.05 m)." | R28: TRUE | S28: TRUE | T28: TRUE | U28: xx | V28: \" target=\"_blank\" data-bs-toggle=\"tooltip\" data-bs-title=\" | W28: \"> | X28: <button type=\"button\" class=\"btn btn-bd-tip-info-hidden btn-sm position-relative\">.<span class=\"position-absolute top-0 start-100 translate-middle\">{{ icon_info }}</span></button></a> | Y28: =IF(M28<>"-",(" "&J28&"_ti"&": "&""""&"<a href=\"&""""&"09_glossary.html#"&J28&V28&K28&": "&M28&W28&""&X28&""""),"-") -> cam_height_ti: "<a href=\"09_glossary.html#cam_height\" target=\"_blank\" data-bs-toggle=\"tooltip\" data-bs-title=\"Camera Height (m): The height from the ground (below snow) to the bottom of the lens (metres; to the nearest 0.05 m).\"><button type=\"button\" class=\"btn btn-bd-tip-info-hidden btn-sm position-relative\">.<span class=\"position-absolute top-0 start-100 translate-middle\">{{ icon_info }}</span></button></a>"
B29: 19 | C29: field | D29: - | E29: **Camera ID** | F29: upper | G29: surv_guide_meta | H29: cam_visit_equip | I29: cam_id | J29: =IF(D29<>"-",I29&"_"&D29,I29) -> cam_id | K29: Camera ID | L29: =IF(VLOOKUP(J29,find_replace!H:H,1,"false")=J29,"TRUE","FALSE") -> TRUE | M29: A unique alphanumeric ID for the camera that distinguishes it from other cameras of the same make or model. | N29: A unique alphanumeric ID for the camera that distinguishes it from other cameras of the same make or model. | O29: =IF(M29=999,"",(" term_"&J29&": """&K29&"""")) -> term_cam_id: "Camera ID" | P29: =IF(M29="-","-",(" def_"&J29&": """&M29&"""")) -> def_cam_id: "A unique alphanumeric ID for the camera that distinguishes it from other cameras of the same make or model." | R29: TRUE | S29: TRUE | T29: TRUE | U29: xx | V29: \" target=\"_blank\" data-bs-toggle=\"tooltip\" data-bs-title=\" | W29: \"> | X29: <button type=\"button\" class=\"btn btn-bd-tip-info-hidden btn-sm position-relative\">.<span class=\"position-absolute top-0 start-100 translate-middle\">{{ icon_info }}</span></button></a> | Y29: =IF(M29<>"-",(" "&J29&"_ti"&": "&""""&"<a href=\"&""""&"09_glossary.html#"&J29&V29&K29&": "&M29&W29&""&X29&""""),"-") -> cam_id_ti: "<a href=\"09_glossary.html#cam_id\" target=\"_blank\" data-bs-toggle=\"tooltip\" data-bs-title=\"Camera ID: A unique alphanumeric ID for the camera that distinguishes it from other cameras of the same make or model.\"><button type=\"button\" class=\"btn btn-bd-tip-info-hidden btn-sm position-relative\">.<span class=\"position-absolute top-0 start-100 translate-middle\">{{ icon_info }}</span></button></a>"
